Traceback (most recent call last):
  File "/opt/hostedtoolcache/Python/3.9.7/x64/lib/python3.9/site-packages/jupyter_cache/executors/utils.py", line 51, in single_nb_execution
    executenb(
  File "/opt/hostedtoolcache/Python/3.9.7/x64/lib/python3.9/site-packages/nbclient/client.py", line 1117, in execute
    return NotebookClient(nb=nb, resources=resources, km=km, **kwargs).execute()
  File "/opt/hostedtoolcache/Python/3.9.7/x64/lib/python3.9/site-packages/nbclient/util.py", line 78, in wrapped
    return just_run(coro(*args, **kwargs))
  File "/opt/hostedtoolcache/Python/3.9.7/x64/lib/python3.9/site-packages/nbclient/util.py", line 57, in just_run
    return loop.run_until_complete(coro)
  File "/opt/hostedtoolcache/Python/3.9.7/x64/lib/python3.9/asyncio/base_events.py", line 642, in run_until_complete
    return future.result()
  File "/opt/hostedtoolcache/Python/3.9.7/x64/lib/python3.9/site-packages/nbclient/client.py", line 558, in async_execute
    await self.async_execute_cell(
  File "/opt/hostedtoolcache/Python/3.9.7/x64/lib/python3.9/site-packages/nbclient/client.py", line 862, in async_execute_cell
    self._check_raise_for_error(cell, exec_reply)
  File "/opt/hostedtoolcache/Python/3.9.7/x64/lib/python3.9/site-packages/nbclient/client.py", line 765, in _check_raise_for_error
    raise CellExecutionError.from_cell_and_msg(cell, exec_reply_content)
nbclient.exceptions.CellExecutionError: An error occurred while executing the following cell:
------------------
%reload_ext autoreload
%autoreload 2
%matplotlib inline

import pymarc
from pymarcspec import MarcSearchParser
import spacy

marc_parser = MarcSearchParser()
with open("data/yale-dvd-records.mrc", "rb") as fo:
    marc_reader = pymarc.MARCReader(fo.read())
marc_records = [r for r in marc_reader]
------------------

[0;31m---------------------------------------------------------------------------[0m
[0;31mFileNotFoundError[0m                         Traceback (most recent call last)
[0;32m/tmp/ipykernel_3861/1794000694.py[0m in [0;36m<module>[0;34m[0m
[1;32m      8[0m [0;34m[0m[0m
[1;32m      9[0m [0mmarc_parser[0m [0;34m=[0m [0mMarcSearchParser[0m[0;34m([0m[0;34m)[0m[0;34m[0m[0;34m[0m[0m
[0;32m---> 10[0;31m [0;32mwith[0m [0mopen[0m[0;34m([0m[0;34m"data/yale-dvd-records.mrc"[0m[0;34m,[0m [0;34m"rb"[0m[0;34m)[0m [0;32mas[0m [0mfo[0m[0;34m:[0m[0;34m[0m[0;34m[0m[0m
[0m[1;32m     11[0m     [0mmarc_reader[0m [0;34m=[0m [0mpymarc[0m[0;34m.[0m[0mMARCReader[0m[0;34m([0m[0mfo[0m[0;34m.[0m[0mread[0m[0;34m([0m[0;34m)[0m[0;34m)[0m[0;34m[0m[0;34m[0m[0m
[1;32m     12[0m [0mmarc_records[0m [0;34m=[0m [0;34m[[0m[0mr[0m [0;32mfor[0m [0mr[0m [0;32min[0m [0mmarc_reader[0m[0;34m][0m[0;34m[0m[0;34m[0m[0m

[0;31mFileNotFoundError[0m: [Errno 2] No such file or directory: 'data/yale-dvd-records.mrc'
FileNotFoundError: [Errno 2] No such file or directory: 'data/yale-dvd-records.mrc'

